{"name": "test_login_1_failed_by_fail_datas[data0]", "uuid": "8d7aa8b3-56db-482f-aa7f-132688f44e0e", "labels": [{"name": "tag", "value": "login"}, {"name": "subSuite", "value": "TestLoginP"}, {"name": "suite", "value": "test_login_pytest"}, {"name": "parentSuite", "value": "TestCases"}, {"name": "host", "value": "G50-75M"}, {"name": "thread", "value": "13544-MainThread"}, {"name": "framework", "value": "pytest"}, {"name": "language", "value": "cpython3"}, {"name": "package", "value": "TestCases.test_login_pytest"}], "historyId": "d1021337b075fdb88fea8a1fac58ed32", "status": "passed", "stop": 1561894597496, "parameters": [{"name": "data", "value": "{'password': 'python', 'user': '13200000000', 'check': '此账号没有经过授权，请联系管理员!'}"}], "fullName": "TestCases.test_login_pytest.TestLoginP#test_login_1_failed_by_fail_datas[data0]", "start": 1561894596132}