{"name": "test_login_0_failed_by_wrong_datas[data3]", "uuid": "cdd2a981-25a5-49e2-b3a8-2255489dd640", "labels": [{"name": "tag", "value": "login"}, {"name": "subSuite", "value": "TestLoginP"}, {"name": "suite", "value": "test_login_pytest"}, {"name": "parentSuite", "value": "TestCases"}, {"name": "host", "value": "G50-75M"}, {"name": "thread", "value": "13544-MainThread"}, {"name": "framework", "value": "pytest"}, {"name": "language", "value": "cpython3"}, {"name": "package", "value": "TestCases.test_login_pytest"}], "historyId": "8c297d3530a4b2fa8edc344d628138ad", "status": "passed", "stop": 1561894592727, "parameters": [{"name": "data", "value": "{'password': 'python', 'user': '1868472055', 'check': '请输入正确的手机号'}"}], "fullName": "TestCases.test_login_pytest.TestLoginP#test_login_0_failed_by_wrong_datas[data3]", "start": 1561894592019}