{"name": "test_login_0_failed_by_wrong_datas[data4]", "uuid": "0d3a2f17-93b9-4f36-9de9-1f488098c99e", "labels": [{"name": "tag", "value": "login"}, {"name": "subSuite", "value": "TestLoginP"}, {"name": "suite", "value": "test_login_pytest"}, {"name": "parentSuite", "value": "TestCases"}, {"name": "host", "value": "G50-75M"}, {"name": "thread", "value": "13544-MainThread"}, {"name": "framework", "value": "pytest"}, {"name": "language", "value": "cpython3"}, {"name": "package", "value": "TestCases.test_login_pytest"}], "historyId": "0cd1a3fa99d0599dc61cd043dcb6fb74", "status": "passed", "stop": 1561894594120, "parameters": [{"name": "data", "value": "{'password': 'python', 'user': '1868472 0553', 'check': '请输入正确的手机号'}"}], "fullName": "TestCases.test_login_pytest.TestLoginP#test_login_0_failed_by_wrong_datas[data4]", "start": 1561894593397}