{"name": "test_login_0_failed_by_wrong_datas[data5]", "uuid": "d7206eab-3926-4051-b542-bad77694ce6c", "labels": [{"name": "tag", "value": "login"}, {"name": "subSuite", "value": "TestLoginP"}, {"name": "suite", "value": "test_login_pytest"}, {"name": "parentSuite", "value": "TestCases"}, {"name": "host", "value": "G50-75M"}, {"name": "thread", "value": "13544-MainThread"}, {"name": "framework", "value": "pytest"}, {"name": "language", "value": "cpython3"}, {"name": "package", "value": "TestCases.test_login_pytest"}], "historyId": "930813980c1d67c94f4cedd1773e7594", "status": "passed", "stop": 1561894595547, "parameters": [{"name": "data", "value": "{'password': 'python', 'user': '186847aa553', 'check': '请输入正确的手机号'}"}], "fullName": "TestCases.test_login_pytest.TestLoginP#test_login_0_failed_by_wrong_datas[data5]", "start": 1561894594770}